<?xml version="1.0" ?>
<!--
  Differential-drive robot + forward-facing camera (Gazebo Harmonic).
  Spawn with pose z = 0.1 (wheel radius) so the wheels sit on the ground;
  the room world's <include> sets that. Topics: /cmd_vel (in), /odom, /camera.
-->
<sdf version="1.10">
  <model name="robot">

    <link name="base_link">
      <inertial>
        <mass>5.0</mass>
        <inertia><ixx>0.08</ixx><iyy>0.1</iyy><izz>0.1</izz>
                 <ixy>0</ixy><ixz>0</ixz><iyz>0</iyz></inertia>
      </inertial>
      <collision name="col"><geometry><box><size>0.4 0.3 0.15</size></box></geometry></collision>
      <visual name="vis"><geometry><box><size>0.4 0.3 0.15</size></box></geometry>
        <material><ambient>0.1 0.3 0.8 1</ambient><diffuse>0.1 0.3 0.8 1</diffuse></material></visual>

      <!-- forward-facing camera at the front of the chassis -->
      <sensor name="camera" type="camera">
        <pose>0.2 0 0.05 0 0 0</pose>
        <always_on>1</always_on>
        <update_rate>30</update_rate>
        <topic>camera</topic>
        <camera>
          <horizontal_fov>2.0</horizontal_fov>
          <image><width>640</width><height>480</height><format>R8G8B8</format></image>
          <clip><near>0.05</near><far>15</far></clip>
        </camera>
      </sensor>
    </link>

    <!-- left wheel -->
    <link name="left_wheel">
      <pose>0 0.2 0 -1.5708 0 0</pose>
      <inertial><mass>0.5</mass>
        <inertia><ixx>0.001</ixx><iyy>0.001</iyy><izz>0.001</izz>
                 <ixy>0</ixy><ixz>0</ixz><iyz>0</iyz></inertia></inertial>
      <collision name="col"><geometry><cylinder><radius>0.1</radius><length>0.05</length></cylinder></geometry></collision>
      <visual name="vis"><geometry><cylinder><radius>0.1</radius><length>0.05</length></cylinder></geometry>
        <material><ambient>0.1 0.1 0.1 1</ambient><diffuse>0.1 0.1 0.1 1</diffuse></material></visual>
    </link>
    <!-- right wheel -->
    <link name="right_wheel">
      <pose>0 -0.2 0 -1.5708 0 0</pose>
      <inertial><mass>0.5</mass>
        <inertia><ixx>0.001</ixx><iyy>0.001</iyy><izz>0.001</izz>
                 <ixy>0</ixy><ixz>0</ixz><iyz>0</iyz></inertia></inertial>
      <collision name="col"><geometry><cylinder><radius>0.1</radius><length>0.05</length></cylinder></geometry></collision>
      <visual name="vis"><geometry><cylinder><radius>0.1</radius><length>0.05</length></cylinder></geometry>
        <material><ambient>0.1 0.1 0.1 1</ambient><diffuse>0.1 0.1 0.1 1</diffuse></material></visual>
    </link>
    <!-- front + rear low-friction casters: stable 4-point base, bottoms
         coplanar with the wheels (center z 0.04 world, radius 0.04). -->
    <link name="caster_front">
      <pose>0.15 0 -0.06 0 0 0</pose>
      <inertial><mass>0.1</mass>
        <inertia><ixx>0.0001</ixx><iyy>0.0001</iyy><izz>0.0001</izz>
                 <ixy>0</ixy><ixz>0</ixz><iyz>0</iyz></inertia></inertial>
      <collision name="col"><geometry><sphere><radius>0.04</radius></sphere></geometry>
        <surface><friction><ode><mu>0.0</mu><mu2>0.0</mu2></ode></friction></surface></collision>
      <visual name="vis"><geometry><sphere><radius>0.04</radius></sphere></geometry></visual>
    </link>
    <link name="caster_rear">
      <pose>-0.15 0 -0.06 0 0 0</pose>
      <inertial><mass>0.1</mass>
        <inertia><ixx>0.0001</ixx><iyy>0.0001</iyy><izz>0.0001</izz>
                 <ixy>0</ixy><ixz>0</ixz><iyz>0</iyz></inertia></inertial>
      <collision name="col"><geometry><sphere><radius>0.04</radius></sphere></geometry>
        <surface><friction><ode><mu>0.0</mu><mu2>0.0</mu2></ode></friction></surface></collision>
      <visual name="vis"><geometry><sphere><radius>0.04</radius></sphere></geometry></visual>
    </link>

    <joint name="left_wheel_joint" type="revolute">
      <parent>base_link</parent><child>left_wheel</child>
      <axis><xyz>0 0 1</xyz><limit><lower>-1e16</lower><upper>1e16</upper></limit></axis>
    </joint>
    <joint name="right_wheel_joint" type="revolute">
      <parent>base_link</parent><child>right_wheel</child>
      <axis><xyz>0 0 1</xyz><limit><lower>-1e16</lower><upper>1e16</upper></limit></axis>
    </joint>
    <joint name="caster_front_joint" type="ball">
      <parent>base_link</parent><child>caster_front</child>
    </joint>
    <joint name="caster_rear_joint" type="ball">
      <parent>base_link</parent><child>caster_rear</child>
    </joint>

    <!-- differential drive: subscribes /cmd_vel, publishes /odom -->
    <plugin filename="gz-sim-diff-drive-system" name="gz::sim::systems::DiffDrive">
      <left_joint>left_wheel_joint</left_joint>
      <right_joint>right_wheel_joint</right_joint>
      <wheel_separation>0.4</wheel_separation>
      <wheel_radius>0.1</wheel_radius>
      <odom_publish_frequency>30</odom_publish_frequency>
      <topic>cmd_vel</topic>
      <odom_topic>odom</odom_topic>
      <frame_id>odom</frame_id>
      <child_frame_id>base_link</child_frame_id>
    </plugin>

    <!-- GROUND TRUTH: publishes the robot's true world pose on /model/robot/pose
         (for verifying the filter estimate in RViz; not used by the filter). -->
    <plugin filename="gz-sim-pose-publisher-system" name="gz::sim::systems::PosePublisher">
      <publish_model_pose>true</publish_model_pose>
      <publish_link_pose>false</publish_link_pose>
      <publish_visual_pose>false</publish_visual_pose>
      <publish_collision_pose>false</publish_collision_pose>
      <publish_sensor_pose>false</publish_sensor_pose>
      <publish_nested_model_pose>false</publish_nested_model_pose>
      <use_pose_vector_msg>false</use_pose_vector_msg>
      <update_frequency>30</update_frequency>
    </plugin>

  </model>
</sdf>
